<?xml version="1.0" ?>
<!-- =================================================================================== -->
<!-- |    This document was autogenerated by xacro from moying_mcr.urdf.xacro          | -->
<!-- |    EDITING THIS FILE BY HAND IS NOT RECOMMENDED                                 | -->
<!-- =================================================================================== -->
<robot name="moying_mcr">
  <material name="black">
    <color rgba="0.0 0.0 0.0 1.0"/>
  </material>
  <material name="blue">
    <color rgba="0.0 0.0 0.8 1.0"/>
  </material>
  <material name="green">
    <color rgba="0.0 0.8 0.0 1.0"/>
  </material>
  <material name="grey">
    <color rgba="0.2 0.2 0.2 1.0"/>
  </material>
  <material name="orange">
    <color rgba="1.0 0.4235294117647059 0.0392156862745098 1.0"/>
  </material>
  <material name="brown">
    <color rgba="0.8705882352941177 0.8117647058823529 0.7647058823529411 1.0"/>
  </material>
  <material name="red">
    <color rgba="0.8 0.0 0.0 1.0"/>
  </material>
  <material name="white">
    <color rgba="1.0 1.0 1.0 1.0"/>
  </material>
  <material name="metal">
    <color rgba="0.768627450980392 0.749019607843137 0.729411764705882 1"/>
  </material>
  <material name="metal_grey">
    <color rgba="0.501960784313725 0.501960784313725 0.501960784313725 1"/>
  </material>
  <material name="metal_white">
    <color rgba="0.866666666666667 0.866666666666667 0.890196078431373 1"/>
  </material>
  <material name="DarkGrey">
    <color rgba="0.3 0.3 0.3 1.0"/>
  </material>
  <material name="Silver">
    <color rgba="0.75 0.75 0.75 1.0"/>
  </material>
  <material name="BrightWhite">
    <color rgba="0.8 0.8 0.8 1.0"/>
  </material>
  <material name="GlassWhite">
    <color rgba="1 1 1 1.0"/>
  </material>
  <material name="Pink">
    <color rgba="1 0.3 0.3 1.0"/>
  </material>
  <link name="base_link"/>
  <link name="mmcomcr"/>
  <joint name="base_joint" type="fixed">
    <origin rpy="0 0 0" xyz="0 0 0"/>
    <parent link="base_link"/>
    <child link="mmcomcr"/>
    <dynamics friction="0.1"/>
  </joint>
  <joint name="right_arm_world_base" type="fixed">
    <origin rpy="0 0 0" xyz="0 0 0"/>
    <parent link="right_arm_base"/>
    <child link="right_arm_elfin_base_link"/>
  </joint>
  <link name="right_arm_elfin_base_link"/>
  <joint name="right_arm_elfin_base_joint" type="fixed">
    <origin rpy="0 0 1.5707963267948966" xyz="0 0 0"/>
    <parent link="right_arm_elfin_base_link"/>
    <child link="right_arm_elfin_base"/>
  </joint>
  <link name="right_arm_elfin_base">
    <inertial>
      <origin rpy="0 0 0" xyz="0.000476057496448 -0.00609847721085 0.0271227961552"/>
      <mass value="1.3364360054428799"/>
      <inertia ixx="0.0033361494" ixy="1.98687e-05" ixz="6.0873e-06" iyy="0.0027567743999999997" iyz="-3.92121e-05" izz="0.0053986008"/>
    </inertial>
    <visual>
      <origin rpy="0 0 0" xyz="0 0 0"/>
      <geometry>
        <mesh filename="package://elfin_description/meshes/elfin3/elfin_base.STL"/>
      </geometry>
      <material name="metal_white"/>
    </visual>
    <collision>
      <origin rpy="0 0 0" xyz="0 0 0"/>
      <geometry>
        <mesh filename="package://elfin_description/meshes/elfin3/elfin_base.STL"/>
      </geometry>
    </collision>
  </link>
  <link name="right_arm_elfin_link1">
    <inertial>
      <origin rpy="0 0 0" xyz="-0.0192425632808 0.120157543892 -2.05350524914e-05"/>
      <mass value="4.6968405580113"/>
      <inertia ixx="0.016185883499999998" ixy="0.0037881237000000002" ixz="-4.944e-07" iyy="0.0097480539" iyz="-1.9776e-06" izz="0.0199814541"/>
    </inertial>
    <visual>
      <origin rpy="0 0 0" xyz="0 0 0"/>
      <geometry>
        <mesh filename="package://elfin_description/meshes/elfin3/elfin_link1.STL"/>
      </geometry>
      <material name="metal"/>
    </visual>
    <collision>
      <origin rpy="0 0 0" xyz="0 0 0"/>
      <geometry>
        <mesh filename="package://elfin_description/meshes/elfin3/elfin_link1.STL"/>
      </geometry>
    </collision>
  </link>
  <joint name="right_arm_elfin_joint1" type="revolute">
    <origin rpy="1.5707963267948966 0 0" xyz="0 0 0.031"/>
    <parent link="right_arm_elfin_base"/>
    <child link="right_arm_elfin_link1"/>
    <axis xyz="0 1 0"/>
    <limit effort="104" lower="-3.14" upper="3.14" velocity="1.57"/>
  </joint>
  <link name="right_arm_elfin_link2">
    <inertial>
      <origin rpy="0 0 0" xyz="-0.0363359816546 0.121774838175 -3.84046105722e-05"/>
      <mass value="1.60578726871323"/>
      <inertia ixx="0.0174527217" ixy="-0.0008180157000000001" ixz="0.0" iyy="0.0016560546" iyz="3.9861e-06" izz="0.016859596199999997"/>
    </inertial>
    <visual>
      <origin rpy="0 0 0" xyz="0 0 0"/>
      <geometry>
        <mesh filename="package://elfin_description/meshes/elfin3/elfin_link2.STL"/>
      </geometry>
      <material name="metal_grey"/>
    </visual>
    <collision>
      <origin rpy="1.57 0 0" xyz="0 0.12 0"/>
      <geometry>
        <cylinder length="0.32" radius="0.05"/>
      </geometry>
    </collision>
  </link>
  <joint name="right_arm_elfin_joint2" type="revolute">
    <origin rpy="0 0 0" xyz="-0.068808 0.1615 0"/>
    <parent link="right_arm_elfin_link1"/>
    <child link="right_arm_elfin_link2"/>
    <axis xyz="-1 0 0"/>
    <limit effort="104" lower="-1.56" upper="1.56" velocity="1.57"/>
  </joint>
  <link name="right_arm_elfin_link3">
    <inertial>
      <origin rpy="0 0 0" xyz="0.0513625008301 -0.0377418700977 -1.41484011876e-05"/>
      <mass value="3.3222006800226"/>
      <inertia ixx="0.0091655271" ixy="0.0022254489" ixz="2.2557e-06" iyy="0.0056319267" iyz="-1.1433e-06" izz="0.0115212195"/>
    </inertial>
    <visual>
      <origin rpy="0 0 0" xyz="0 0 0"/>
      <geometry>
        <mesh filename="package://elfin_description/meshes/elfin3/elfin_link3.STL"/>
      </geometry>
      <material name="metal"/>
    </visual>
    <collision>
      <origin rpy="0 0 0" xyz="0 0 0"/>
      <geometry>
        <mesh filename="package://elfin_description/meshes/elfin3/elfin_link3.STL"/>
      </geometry>
    </collision>
  </link>
  <joint name="right_arm_elfin_joint3" type="revolute">
    <origin rpy="-3.141592653589793 0 0" xyz="0 0.266 0"/>
    <parent link="right_arm_elfin_link2"/>
    <child link="right_arm_elfin_link3"/>
    <axis xyz="1 0 0"/>
    <limit effort="69" lower="0.00" upper="3.14" velocity="1.57"/>
  </joint>
  <link name="right_arm_elfin_link4">
    <inertial>
      <origin rpy="0 0 0" xyz="-0.0580853772834 0.10002233137 -3.45203877103e-06"/>
      <mass value="1.1441233731729"/>
      <inertia ixx="0.0073628211" ixy="0.0025633095" ixz="3.399e-07" iyy="0.0029589221999999997" iyz="-9.888e-07" izz="0.0088114749"/>
    </inertial>
    <visual>
      <origin rpy="0 0 0" xyz="0 0 0"/>
      <geometry>
        <mesh filename="package://elfin_description/meshes/elfin3/elfin_link4.STL"/>
      </geometry>
      <material name="metal_grey"/>
    </visual>
    <collision>
      <origin rpy="1.57 0 0" xyz="0 0 0"/>
      <geometry>
        <cylinder length="0.15" radius="0.05"/>
      </geometry>
    </collision>
  </link>
  <joint name="right_arm_elfin_joint4" type="revolute">
    <origin rpy="3.141592653589793 0 0" xyz="0.068808 -0.10523 0"/>
    <parent link="right_arm_elfin_link3"/>
    <child link="right_arm_elfin_link4"/>
    <axis xyz="0 1 0"/>
    <limit effort="69" lower="-3.14" upper="3.14" velocity="1.57"/>
  </joint>
  <link name="right_arm_elfin_link5">
    <inertial>
      <origin rpy="0 0 0" xyz="-0.0158710385319 -0.0365214098995 4.94388107361e-07"/>
      <mass value="2.49371418225432"/>
      <inertia ixx="0.0059859171" ixy="0.0014567805" ixz="6.18e-08" iyy="0.0034872812999999997" iyz="-3.399e-07" izz="0.0075907395"/>
    </inertial>
    <visual>
      <origin rpy="0 0 0" xyz="0 0 0"/>
      <geometry>
        <mesh filename="package://elfin_description/meshes/elfin3/elfin_link5.STL"/>
      </geometry>
      <material name="metal"/>
    </visual>
    <collision>
      <origin rpy="0 0 0" xyz="0 0 0"/>
      <geometry>
        <mesh filename="package://elfin_description/meshes/elfin3/elfin_link5.STL"/>
      </geometry>
    </collision>
  </link>
  <joint name="right_arm_elfin_joint5" type="revolute">
    <origin rpy="-3.141592653589793 0 0" xyz="0 0.21877 0"/>
    <parent link="right_arm_elfin_link4"/>
    <child link="right_arm_elfin_link5"/>
    <axis xyz="1 0 0"/>
    <limit effort="34" lower="-3.14" upper="3.14" velocity="1.57"/>
  </joint>
  <link name="right_arm_elfin_link6">
    <inertial>
      <origin rpy="0 0 0" xyz="-0.0009237 -0.042691 -0.0003367"/>
      <mass value="0.45519408"/>
      <inertia ixx="0.0005996762999999999" ixy="4.326e-06" ixz="-8.9301e-06" iyy="0.0006053928" iyz="1.545e-07" izz="0.0006024263999999999"/>
    </inertial>
    <visual>
      <origin rpy="0 0 0" xyz="0 0 0"/>
      <geometry>
        <mesh filename="package://elfin_description/meshes/elfin3/elfin_link6.STL"/>
      </geometry>
      <material name="metal_white"/>
    </visual>
    <collision>
      <origin rpy="1.57 0 0" xyz="0 0 0"/>
      <geometry>
        <cylinder length="0.2" radius="0.04"/>
      </geometry>
    </collision>
  </link>
  <joint name="right_arm_elfin_joint6" type="revolute">
    <origin rpy="-3.141592653589793 0 -3.141592653589793" xyz="0 -0.1065 0"/>
    <parent link="right_arm_elfin_link5"/>
    <child link="right_arm_elfin_link6"/>
    <axis xyz="0 -1 0"/>
    <limit effort="34" lower="-3.14" upper="3.14" velocity="1.57"/>
  </joint>
  <link name="right_arm_elfin_end_link"/>
  <joint name="right_arm_elfin_end_joint" type="fixed">
    <origin rpy="1.5707963267948966 3.141592653589793 0" xyz="0 -0.19 0"/>
    <parent link="right_arm_elfin_link6"/>
    <child link="right_arm_elfin_end_link"/>
  </joint>
  <joint name="vehicle_body_joint" type="fixed">
    <origin rpy="0 0 0" xyz="0 0 0.03"/>
    <parent link="base_link"/>
    <child link="vehicle_body"/>
  </joint>
  <!-- Vehicle body-->
  <link name="vehicle_body">
    <inertial>
      <mass value="100"/>
      <origin rpy="0 0 0" xyz="0 0 -0.03 "/>
      <inertia ixx="8.450033333333332" ixy="0" ixz="0" iyy="3.307366666666667" iyz="0" izz="11.590733333333333"/>
    </inertial>
    <visual>
      <origin rpy="1.5707963267948966 0 1.5707963267948966" xyz="0 0 -0.03 "/>
      <geometry>
        <mesh filename="package://moying_chassis_description/meshes/MQ60.STL" scale="0.001 0.001 0.001"/>
      </geometry>
      <material name="Silver"/>
    </visual>
    <collision>
      <origin rpy="0 0 0" xyz="0 0 0.387"/>
      <geometry>
        <box size="0.6 0.4 0.234"/>
      </geometry>
    </collision>
  </link>
  <link name="ex_link"/>
  <joint name="ex_joint" type="fixed">
    <origin rpy="0 0 -1.5707963267948966" xyz="0.35 0 0.75"/>
    <parent link="base_link"/>
    <child link="ex_link"/>
  </joint>
  <!-- Body -->
  <joint name="body_base_joint" type="fixed">
    <origin rpy="0 0 0" xyz="0.27 0 0.78"/>
    <parent link="vehicle_body"/>
    <child link="body_base"/>
  </joint>
  <link name="body_base">
    <inertial>
      <mass value="1"/>
      <origin rpy="0 0 0" xyz="0 0 0.1 "/>
      <inertia ixx="0.003958333333333334" ixy="0" ixz="0" iyy="0.003958333333333334" iyz="0" izz="0.0012500000000000002"/>
    </inertial>
    <visual>
      <origin rpy="1.5707963267948966 0 -1.5707963267948966" xyz="0 0 0 "/>
      <geometry>
        <mesh filename="package://moying_mcr_description/meshes/Body_base.STL"/>
      </geometry>
      <material name="white"/>
    </visual>
    <collision>
      <origin rpy="0 0 -1.5707963267948966" xyz="0 0 0.3"/>
      <geometry>
        <cylinder length="0.4" radius="0.14"/>
      </geometry>
    </collision>
  </link>
  <joint name="body_joint" type="fixed">
    <!-- Extention shell -->
    <parent link="body_base"/>
    <child link="body"/>
    <axis xyz="0 0 1"/>
    <limit effort="104" lower="-3.16" upper="3.16" velocity="1.57"/>
  </joint>
  <link name="body">
    <inertial>
      <mass value="5"/>
      <origin rpy="0 0 0" xyz="0 0 0.22 "/>
      <inertia ixx="0.10416666666666667" ixy="0.0" ixz="0.0" iyy="0.10416666666666667" iyz="0.0" izz="0.075"/>
    </inertial>
    <visual>
      <origin rpy="0 0 1.5707963267948966" xyz="0 0 0 "/>
      <geometry>
        <mesh filename="package://moying_mcr_description/meshes/Body.STL"/>
      </geometry>
      <material name="white"/>
    </visual>
    <!-- <collision>
        <origin rpy="0 0 ${pi/2}" xyz="0 0 0"/>
        <geometry>
          <mesh filename="package://moying_mcr_description/meshes/Body.STL" />
        </geometry>
      </collision> -->
  </link>
  <!-- Manipulators -->
  <link name="right_arm_base"/>
  <joint name="right_arm_base_joint" type="fixed">
    <origin rpy="1.5707963267948966 1.5707963267948966 0" xyz="0 -0.087 0.390"/>
    <parent link="body"/>
    <child link="right_arm_base"/>
    <axis xyz="0 0 1"/>
  </joint>

  <joint name="extention_shell_joint" type="fixed">
    <origin rpy="0 0 0" xyz="0 0 0"/>
    <parent link="vehicle_body"/>
    <child link="extention_shell"/>
  </joint>
  <link name="extention_shell">
    <visual>
      <origin rpy="0 0 -1.5707963267948966" xyz="0 0 0 "/>
      <geometry>
        <mesh filename="package://moying_mcr_description/meshes/CD6003_TopCover.STL" scale="0.001 0.001 0.001"/>
      </geometry>
      <material name="Silver"/>
    </visual>
    <collision>
      <origin rpy="0 0 0" xyz="0 0 0.53"/>
      <geometry>
        <box size="1.05 0.62 0.54"/>
      </geometry>
    </collision>
  </link>
</robot>
