<mujoco model="pr2">
  <compiler angle="radian" meshdir="./meshes/"/>

  <asset>
    <mesh name="base" content_type="model/stl" file="base.stl"/>
    <mesh name="base_L" content_type="model/stl" file="base_L.stl"/>
    <mesh name="caster" content_type="model/stl" file="caster.stl"/>
    <mesh name="caster_L" content_type="model/stl" file="caster_L.stl"/>
    <mesh name="wheel" content_type="model/stl" file="wheel.stl"/>
    <mesh name="torso_lift" content_type="model/stl" file="torso_lift.stl"/>
    <mesh name="torso_lift_L" content_type="model/stl" file="torso_lift_L.stl"/>
    <mesh name="head_pan" content_type="model/stl" file="head_pan.stl"/>
    <mesh name="head_pan_L" content_type="model/stl" file="head_pan_L.stl"/>
    <mesh name="head_tilt" content_type="model/stl" file="head_tilt.stl"/>
    <mesh name="head_tilt_L" content_type="model/stl" file="head_tilt_L.stl"/>
    <mesh name="tilting_hokuyo" content_type="model/stl" file="tilting_hokuyo.stl"/>
    <mesh name="tilting_hokuyo_L" content_type="model/stl" file="tilting_hokuyo_L.stl"/>
    <mesh name="shoulder_pan" content_type="model/stl" file="shoulder_pan.stl"/>
    <mesh name="shoulder_lift" content_type="model/stl" file="shoulder_lift.stl"/>
    <mesh name="upper_arm_roll" content_type="model/stl" file="upper_arm_roll.stl"/>
    <mesh name="upper_arm_roll_L" content_type="model/stl" file="upper_arm_roll_L.stl"/>
    <mesh name="upper_arm" content_type="model/stl" file="upper_arm.stl"/>
    <mesh name="forearm_roll" content_type="model/stl" file="forearm_roll.stl"/>
    <mesh name="forearm_roll_L" content_type="model/stl" file="forearm_roll_L.stl"/>
    <mesh name="elbow_flex" content_type="model/stl" file="elbow_flex.stl"/>
    <mesh name="forearm" content_type="model/stl" file="forearm.stl"/>
    <mesh name="wrist_flex" content_type="model/stl" file="wrist_flex.stl"/>
    <mesh name="wrist_roll" content_type="model/stl" file="wrist_roll.stl"/>
    <mesh name="wrist_roll_L" content_type="model/stl" file="wrist_roll_L.stl"/>
    <mesh name="gripper_palm" content_type="model/stl" file="gripper_palm.stl"/>
    <mesh name="l_finger" content_type="model/stl" file="l_finger.stl"/>
    <mesh name="l_finger_tip" content_type="model/stl" file="l_finger_tip.stl"/>

  </asset>

  <worldbody>
    <!-- <body name="base_link" pos="-1.7 0.0 0.2" quat="0 0 0 1"> -->
    <body name="base_link" pos="-3.0 2.0 0.2" quat="0.7071 0 0 -0.7071">
    <!-- <body name="base_link" pos="-3.0 -2.0 0.2" quat="0.7071 0 0 0.7071"> -->
      <freejoint/>
      <body name="pr2_base" pos="0 0 -0.051">
        <site name="pr2_base_sensor" pos="0 0 0" size="0.001"/>
      </body>
      <inertial pos="-0.061 0 0.1465" quat="0.973598 0.00176355 -0.228065 -0.00944331" mass="116" diaginertia="6.29388 5.66925 3.04177"/>
      <geom type="mesh" contype="2" conaffinity="2" group="1" density="0" rgba="1 1 1 1" mesh="base"/>
      
      <body name="base_bellow_link" pos="-0.29 0 0.8">
        <inertial pos="0 0 0" mass="1" diaginertia="0.01 0.01 0.01"/>
        <geom size="0.025 0.185 0.15" type="box" contype="0" conaffinity="0" group="1" density="0" rgba="0.1 0.1 0.1 1"/>
      </body>
      <body name="base_laser_link" pos="0.275 0 0.252">
        <inertial pos="0 0 0" quat="0.707107 0.707107 0 0" mass="0.001" diaginertia="0.0001 0.0001 1e-06"/>
      </body>

      <body name="fl_caster_rotation_link" pos="0.2246 0.2246 0.0282">
        <inertial pos="0 0 0.07" quat="0.589921 -0.182261 -0.205712 0.759247" mass="3.47308" diaginertia="0.0153925 0.0125446 0.0114568"/>
        <joint name="fl_caster_rotation_joint" pos="0 0 0" axis="0 0 1" actuatorfrcrange="-6.5 6.5" damping="0.1"/>
        <geom type="mesh" contype="0" conaffinity="0" group="1" density="0" mesh="caster"/>
        <body name="fl_caster_l_wheel_link" pos="0 0.049 0">
          <inertial pos="0 0 0" quat="0.589921 -0.182261 -0.205712 0.759247" mass="0.44036" diaginertia="0.0153925 0.0125446 0.0114568"/>
          <joint name="fl_caster_l_wheel_joint" pos="0 0 0" axis="0 1 0" actuatorfrcrange="-7 7" damping="1"/>
          <geom type="mesh" group="1" density="0" mesh="wheel"/>
        </body>
        <body name="fl_caster_r_wheel_link" pos="0 -0.049 0">
          <inertial pos="0 0 0" quat="0.589921 -0.182261 -0.205712 0.759247" mass="0.44036" diaginertia="0.0153925 0.0125446 0.0114568"/>
          <joint name="fl_caster_r_wheel_joint" pos="0 0 0" axis="0 1 0" actuatorfrcrange="-7 7" damping="1"/>
          <geom type="mesh" group="1" density="0" mesh="wheel"/>
        </body>
      </body>

      <body name="fr_caster_rotation_link" pos="0.2246 -0.2246 0.0282">
        <inertial pos="0 0 0.07" quat="0.589921 -0.182261 -0.205712 0.759247" mass="3.47308" diaginertia="0.0153925 0.0125446 0.0114568"/>
        <joint name="fr_caster_rotation_joint" pos="0 0 0" axis="0 0 1" actuatorfrcrange="-6.5 6.5" damping="0.1"/>
        <geom type="mesh" contype="0" conaffinity="0" group="1" density="0" mesh="caster"/>
        <body name="fr_caster_l_wheel_link" pos="0 0.049 0">
          <inertial pos="0 0 0" quat="0.589921 -0.182261 -0.205712 0.759247" mass="0.44036" diaginertia="0.0153925 0.0125446 0.0114568"/>
          <joint name="fr_caster_l_wheel_joint" pos="0 0 0" axis="0 1 0" actuatorfrcrange="-7 7" damping="1"/>
          <geom type="mesh" group="1" density="0" mesh="wheel"/>
        </body>
        <body name="fr_caster_r_wheel_link" pos="0 -0.049 0">
          <inertial pos="0 0 0" quat="0.589921 -0.182261 -0.205712 0.759247" mass="0.44036" diaginertia="0.0153925 0.0125446 0.0114568"/>
          <joint name="fr_caster_r_wheel_joint" pos="0 0 0" axis="0 1 0" actuatorfrcrange="-7 7" damping="1"/>
          <geom type="mesh" group="1" density="0" mesh="wheel"/>
        </body>
      </body>

      <body name="bl_caster_rotation_link" pos="-0.2246 0.2246 0.0282">
        <inertial pos="0 0 0.07" quat="0.589921 -0.182261 -0.205712 0.759247" mass="3.47308" diaginertia="0.0153925 0.0125446 0.0114568"/>
        <joint name="bl_caster_rotation_joint" pos="0 0 0" axis="0 0 1" actuatorfrcrange="-6.5 6.5" damping="0.1"/>
        <geom type="mesh" contype="0" conaffinity="0" group="1" density="0" mesh="caster"/>
        <body name="bl_caster_l_wheel_link" pos="0 0.049 0">
          <inertial pos="0 0 0" quat="0.589921 -0.182261 -0.205712 0.759247" mass="0.44036" diaginertia="0.0153925 0.0125446 0.0114568"/>
          <joint name="bl_caster_l_wheel_joint" pos="0 0 0" axis="0 1 0" actuatorfrcrange="-7 7" damping="1"/>
          <geom type="mesh" group="1" density="0" mesh="wheel"/>
        </body>
        <body name="bl_caster_r_wheel_link" pos="0 -0.049 0">
          <inertial pos="0 0 0" quat="0.589921 -0.182261 -0.205712 0.759247" mass="0.44036" diaginertia="0.0153925 0.0125446 0.0114568"/>
          <joint name="bl_caster_r_wheel_joint" pos="0 0 0" axis="0 1 0" actuatorfrcrange="-7 7" damping="1"/>
          <geom type="mesh" group="1" density="0" mesh="wheel"/>
        </body>
      </body>

      <body name="br_caster_rotation_link" pos="-0.2246 -0.2246 0.0282">
        <inertial pos="0 0 0.07" quat="0.589921 -0.182261 -0.205712 0.759247" mass="3.47308" diaginertia="0.0153925 0.0125446 0.0114568"/>
        <joint name="br_caster_rotation_joint" pos="0 0 0" axis="0 0 1" actuatorfrcrange="-6.5 6.5" damping="0.1"/>
        <geom type="mesh" contype="0" conaffinity="0" group="1" density="0" mesh="caster"/>
        <body name="br_caster_l_wheel_link" pos="0 0.049 0">
          <inertial pos="0 0 0" quat="0.589921 -0.182261 -0.205712 0.759247" mass="0.44036" diaginertia="0.0153925 0.0125446 0.0114568"/>
          <joint name="br_caster_l_wheel_joint" pos="0 0 0" axis="0 1 0" actuatorfrcrange="-7 7" damping="1"/>
          <geom type="mesh" group="1" density="0" mesh="wheel"/>
        </body>
        <body name="br_caster_r_wheel_link" pos="0 -0.049 0">
          <inertial pos="0 0 0" quat="0.589921 -0.182261 -0.205712 0.759247" mass="0.44036" diaginertia="0.0153925 0.0125446 0.0114568"/>
          <joint name="br_caster_r_wheel_joint" pos="0 0 0" axis="0 1 0" actuatorfrcrange="-7 7" damping="1"/>
          <geom type="mesh" group="1" density="0" mesh="wheel"/>
        </body>
      </body>

      <body name="torso_lift_link" pos="-0.05 0 0.739675">
        <inertial pos="-0.1 0 -0.0885" quat="0.999335 0.00762625 0.0354529 0.00371175" mass="36.248" diaginertia="2.78307 2.51045 0.514581"/>
        <joint name="torso_lift_joint" pos="0 0 0" axis="0 0 1" type="slide" range="0 0.33" actuatorfrcrange="-10000 10000" damping="20000"/>
        <geom type="mesh" contype="0" conaffinity="0" group="1" density="0" rgba="0.9 0.9 0.9 1" mesh="torso_lift"/>
        
        <body name="l_torso_lift_side_plate_link" pos="0.0535 0.209285 0.176625">
          <inertial pos="-0.0625 0 0.05" mass="0.1" diaginertia="0.001 0.001 0.001"/>
        </body>
        <body name="r_torso_lift_side_plate_link" pos="0.0535 -0.209285 0.176625">
          <inertial pos="-0.0625 0 0.05" mass="0.1" diaginertia="0.001 0.001 0.001"/>
        </body>
        <body name="imu_link" pos="-0.02977 -0.1497 0.164" quat="0 0 1 0">
          <inertial pos="0 0 0" quat="0.707107 0.707107 0 0" mass="0.001" diaginertia="0.0001 0.0001 1e-06"/>
        </body>

        <body name="head_pan_link" pos="-0.01707 0 0.38145">
          <inertial pos="0.010907 0.031693 0.090507" quat="-0.0432724 0.73785 -0.0944754 0.666918" mass="6.339" diaginertia="0.0583935 0.0461226 0.0321798"/>
          <joint name="head_pan_joint" pos="0 0 0" axis="0 0 1" range="-3.007 3.007" actuatorfrcrange="-2.645 2.645" damping="0.5"/>
          <geom type="mesh" contype="0" conaffinity="0" group="1" density="0" rgba="0 0 0.8 1" mesh="head_pan"/>
          <body name="head_tilt_link" pos="0.068 0 0">
            <inertial pos="0.001716 -0.019556 0.055002" quat="0.0812252 0.702704 0.0664272 0.703702" mass="4.479" diaginertia="0.0679001 0.0541425 0.02421"/>
            <joint name="head_tilt_joint" pos="0 0 0" axis="0 1 0" range="-0.471238 1.39626" actuatorfrcrange="-18 18" damping="10"/>
            <geom type="mesh" contype="0" conaffinity="0" group="1" density="0" rgba="0 0.8 0 1" mesh="head_tilt"/>
            <body name="head_plate_frame" pos="0.0232 0 0.0645">
              <inertial pos="0 0 0" mass="0.01" diaginertia="0.001 0.001 0.001"/>
              <geom size="0.005 0.005 0.005" type="box" contype="0" conaffinity="0" group="1" density="0" rgba="0 0 0.8 1"/>
              <geom size="0.005 0.005 0.005" type="box" rgba="0 0 0.8 1"/>
              <body name="sensor_mount_link">
                <inertial pos="0 0 0" quat="0.5 0.5 -0.5 0.5" mass="0.05" diaginertia="0.004 0.004 0.004"/>
                <body name="high_def_frame" pos="0.046457 -0.11 0.0546">
                  <inertial pos="0 0 0" mass="0.01" diaginertia="0.001 0.001 0.001"/>
                  <body name="high_def_optical_frame" quat="0.5 -0.5 0.5 -0.5">
                    <inertial pos="0 0 0" mass="0.01" diaginertia="0.001 0.001 0.001"/>
                  </body>
                </body>
                <body name="double_stereo_link">
                  <inertial pos="0 0 0" quat="0.5 0.5 -0.5 0.5" mass="0.1" diaginertia="0.004 0.004 0.004"/>
                  <body name="wide_stereo_link" pos="0.045 0.03 0.0501">
                    <inertial pos="0 0 0" mass="0.1" diaginertia="0.01 0.01 0.01"/>
                    <body name="wide_stereo_optical_frame" quat="0.5 -0.5 0.5 -0.5"/>
                    <body name="wide_stereo_l_stereo_camera_frame">
                      <inertial pos="0 0 0" mass="0.01" diaginertia="0.001 0.001 0.001"/>
                      <body name="wide_stereo_l_stereo_camera_optical_frame" quat="0.5 -0.5 0.5 -0.5"/>
                      <body name="wide_stereo_r_stereo_camera_frame" pos="0 -0.09 0">
                        <inertial pos="0 0 0" mass="0.01" diaginertia="0.001 0.001 0.001"/>
                        <body name="wide_stereo_r_stereo_camera_optical_frame" quat="0.5 -0.5 0.5 -0.5"/>
                      </body>
                    </body>
                  </body>
                  <body name="narrow_stereo_link" pos="0.045 0.06 0.0501">
                    <inertial pos="0 0 0" mass="0.1" diaginertia="0.01 0.01 0.01"/>
                    <body name="narrow_stereo_optical_frame" quat="0.5 -0.5 0.5 -0.5"/>
                    <body name="narrow_stereo_l_stereo_camera_frame">
                      <inertial pos="0 0 0" mass="0.01" diaginertia="0.001 0.001 0.001"/>
                      <body name="narrow_stereo_l_stereo_camera_optical_frame" quat="0.5 -0.5 0.5 -0.5"/>
                      <body name="narrow_stereo_r_stereo_camera_frame" pos="0 -0.09 0">
                        <inertial pos="0 0 0" mass="0.01" diaginertia="0.001 0.001 0.001"/>
                        <body name="narrow_stereo_r_stereo_camera_optical_frame" quat="0.5 -0.5 0.5 -0.5"/>
                      </body>
                    </body>
                  </body>
                </body>
              </body>
              <body name="projector_wg6802418_frame" pos="0 0.11 0.0546">
                <inertial pos="0 0 0" mass="0.01" diaginertia="0.001 0.001 0.001"/>
                <body name="projector_wg6802418_child_frame" quat="0.707107 0 -0.707107 0">
                  <inertial pos="0 0 0" mass="0.01" diaginertia="0.001 0.001 0.001"/>
                </body>
              </body>
            </body>
          </body>
        </body>
        
        <body name="laser_tilt_mount_link" pos="0.09893 0 0.227">
          <inertial pos="-0.001136 0.00167 -0.00713" quat="0.991286 0.0500966 -0.0484425 0.111783" mass="0.591" diaginertia="0.00120457 0.00108175 0.000787921"/>
          <joint name="laser_tilt_mount_joint" pos="0 0 0" axis="0 1 0" range="-0.7854 1.48353" actuatorfrcrange="-0.65 0.65" damping="0.008"/>
          <geom type="mesh" contype="0" conaffinity="0" group="1" density="0" rgba="0.8 0 0 1" mesh="tilting_hokuyo"/>
          <body name="laser_tilt_link" pos="0 0 0.03">
            <inertial pos="0 0 0" quat="0.707107 0.707107 0 0" mass="0.001" diaginertia="0.0001 0.0001 1e-06"/>
          </body>
        </body>

        <body name="r_shoulder_pan_link" pos="0 -0.188 0">
          <inertial pos="-0.001201 0.024513 -0.098231" quat="0.927482 -0.0876561 0.0740595 -0.355821" mass="25.7993" diaginertia="0.934201 0.837701 0.242033"/>
          <joint name="r_shoulder_pan_joint" pos="0 0 0" axis="0 0 1" range="-2.2854 0.000" actuatorfrcrange="-30 30" damping="10"/>
          <geom type="mesh" contype="0" conaffinity="0" group="1" density="0" rgba="0 0 0.8 1" mesh="shoulder_pan"/>
          <body name="r_shoulder_lift_link" pos="0.1 0 0">
            <inertial pos="0.02195 -0.02664 -0.03127" quat="0.791779 0.478014 0.238985 0.295762" mass="2.74988" diaginertia="0.0261874 0.0207302 0.0151681"/>
            <joint name="r_shoulder_lift_joint" pos="0 0 0" axis="0 1 0" range="-0.5236 1.3963" actuatorfrcrange="-200 200" damping="10"/>
            <geom type="mesh" contype="0" conaffinity="0" group="1" density="0" rgba="0.7 0.7 0.7 1" mesh="shoulder_lift"/>
            <body name="r_upper_arm_roll_link">
              <inertial pos="0 0 0" mass="0.1" diaginertia="0.01 0.01 0.01"/>
              <joint name="r_upper_arm_roll_joint" pos="0 0 0" axis="1 0 0" range="-3.9 0.000" actuatorfrcrange="-100 100" damping="0.1"/>
              <geom type="mesh" contype="0" conaffinity="0" group="1" density="0" mesh="upper_arm_roll"/>
              <body name="r_upper_arm_link">
                <inertial pos="0.21398 -0.01621 -0.0002" quat="-0.0450196 0.697462 -0.088537 0.709705" mass="6.01769" diaginertia="0.0761385 0.0749307 0.0151327"/>
                <geom type="mesh" contype="0" conaffinity="0" group="1" density="0" rgba="0 0.8 0 1" mesh="upper_arm"/>
                <body name="r_elbow_flex_link" pos="0.4 0 0">
                  <inertial pos="0.01014 0.00032 -0.01211" quat="0.308784 0.646797 0.639077 0.279083" mass="1.90327" diaginertia="0.00441852 0.00396477 0.00308977"/>
                  <joint name="r_elbow_flex_joint" pos="0 0 0" axis="0 1 0" range="-2.3213 0" actuatorfrcrange="-100 100" damping="1"/>
                  <geom type="mesh" contype="0" conaffinity="0" group="1" density="0" rgba="0.7 0.7 0.7 1" mesh="elbow_flex"/>
                  <body name="r_forearm_roll_link">
                    <inertial pos="0 0 0" mass="0.1" diaginertia="0.01 0.01 0.01"/>
                    <joint name="r_forearm_roll_joint" pos="0 0 0" axis="1 0 0" range="-300 300" actuatorfrcrange="-30 30" damping="0.1"/>
                    <geom type="mesh" contype="0" conaffinity="0" group="1" density="0" mesh="forearm_roll"/>
                    <body name="r_forearm_link">
                      <inertial pos="0.18791 -0.00017 -0.00912" quat="-0.000586594 0.726286 -0.00396869 0.687381" mass="2.57968" diaginertia="0.0166326 0.0150775 0.00360892"/>
                      <geom type="mesh" contype="2" conaffinity="2" group="1" density="0" rgba="0.7 0.7 0.7 1" mesh="forearm"/>
                      <body name="r_wrist_flex_link" pos="0.321 0 0">
                        <inertial pos="-0.00157 0 -0.00075" quat="0.695976 0.696411 -0.12356 0.123942" mass="0.61402" diaginertia="0.000652771 0.000643391 0.000198244"/>
                        <joint name="r_wrist_flex_joint" pos="0 0 0" axis="0 1 0" range="-2.18 0" actuatorfrcrange="-30 30" damping="0.1"/>
                        <geom type="mesh" contype="0" conaffinity="0" group="1" density="0" rgba="0.7 0.7 0.7 1" mesh="wrist_flex"/>
                        <body name="r_wrist_roll_link">
                          <inertial pos="0 0 0" mass="0.1" diaginertia="0.01 0.01 0.01"/>
                          <joint name="r_wrist_roll_joint" pos="0 0 0" axis="1 0 0" range="-300 300" actuatorfrcrange="-10 10" damping="0.1"/>
                          <geom type="mesh" contype="0" conaffinity="0" group="1" density="0" mesh="wrist_roll"/>
                          <body name="r_wrist_ft_link" pos="0.03 0 0">
                            <inertial pos="0 0 0" mass="0.0001" diaginertia="1e-6 1e-6 1e-6"/>
                            <site name="r_wrist_ft_site" type="cylinder" pos="0 0 0" zaxis="1 0 0" size="0.02 0.001" rgba="0 0 1 1"/>                          
                            <body name="r_gripper_palm_link" pos="-0.03 0 0">
                              <inertial pos="0.06623 0.00053 -0.00119" quat="-0.0181842 0.706274 0.0160771 0.707523" mass="0.58007" diaginertia="0.000865637 0.000678178 0.000351471"/>
                              <geom type="mesh" contype="0" conaffinity="0" group="1" density="0" rgba="0.8 0 0 1" mesh="gripper_palm"/>
                              <body name="r_gripper_led_frame" pos="0.0513 0 0.0244"/>
                              <body name="r_gripper_tool_frame" pos="0.18 0 0"/>
                              <body name="r_gripper_l_finger_link" pos="0.07691 0.01 0">
                                <inertial pos="0.03598 0.0173 -0.00164" quat="0.57444 0.429111 0.518782 0.465562" mass="0.17126" diaginertia="0.00019774 0.000181336 7.66239e-05"/>
                                <joint name="r_gripper_l_finger_joint" pos="0 0 0" axis="0 0 1" range="0 0.548" actuatorfrcrange="-1000 1000" damping="0.02"/>
                                <geom type="mesh" contype="0" conaffinity="0" group="1" density="0" rgba="0.7 0.7 0.7 1" mesh="l_finger"/>
                                <geom type="mesh" rgba="0.7 0.7 0.7 1" mesh="l_finger"/>
                                <body name="r_gripper_l_finger_tip_link" pos="0.09137 0.00495 0">
                                  <inertial pos="0.00423 0.00284 0" quat="0.249588 0.661594 -0.249588 0.661594" mass="0.04419" diaginertia="1.54177e-05 1.50049e-05 3.23624e-06"/>
                                  <joint name="r_gripper_l_finger_tip_joint" pos="0 0 0" axis="0 0 -1" range="0 0.548" actuatorfrcrange="-1000 1000" damping="0.1"/>
                                  <geom type="mesh" contype="0" conaffinity="0" group="1" density="0" rgba="0 0.8 0 1" mesh="l_finger_tip"/>
                                  <geom type="mesh" rgba="0 0.8 0 1" mesh="l_finger_tip"/>
                                </body>
                              </body>
                              <body name="r_gripper_r_finger_link" pos="0.07691 -0.01 0">
                                <inertial pos="0.03576 -0.01736 -0.00095" quat="0.474684 0.510909 0.446353 0.560727" mass="0.17389" diaginertia="0.000198903 0.00018134 7.66847e-05"/>
                                <joint name="r_gripper_r_finger_joint" pos="0 0 0" axis="0 0 -1" range="0 0.548" actuatorfrcrange="-1000 1000" damping="0.02"/>
                                <geom quat="0 1 0 0" type="mesh" contype="0" conaffinity="0" group="1" density="0" rgba="0.7 0.7 0.7 1" mesh="l_finger"/>
                                <geom quat="0 1 0 0" type="mesh" rgba="0.7 0.7 0.7 1" mesh="l_finger"/>
                                <body name="r_gripper_r_finger_tip_link" pos="0.09137 -0.00495 0">
                                  <inertial pos="0.00423 -0.00284 0" quat="-0.249588 0.661594 0.249588 0.661594" mass="0.04419" diaginertia="1.54177e-05 1.50049e-05 3.23624e-06"/>
                                  <joint name="r_gripper_r_finger_tip_joint" pos="0 0 0" axis="0 0 1" range="0 0.548" actuatorfrcrange="-1000 1000" damping="0.1"/>
                                  <geom quat="0 1 0 0" type="mesh" contype="0" conaffinity="0" group="1" density="0" rgba="0 0.8 0 1" mesh="l_finger_tip"/>
                                  <geom quat="0 1 0 0" type="mesh" rgba="0 0.8 0 1" mesh="l_finger_tip"/>
                                  <body name="r_gripper_l_finger_tip_frame">
                                    <inertial pos="0 0 0" mass="0.001" diaginertia="1e-06 1e-06 1e-06"/>
                                    <joint name="r_gripper_joint" pos="0 0 0" axis="0 1 0" type="slide" range="0 0.09" actuatorfrcrange="-1000 1000" damping="10"/>
                                  </body>
                                </body>
                              </body>
                            </body>
                          </body>
                        </body>
                      </body>
                    </body>
                    <body name="r_forearm_cam_frame" pos="0.135 0 0.044" quat="0.679288 0.679288 -0.196387 0.196387">
                      <inertial pos="0 0 0" mass="0.01" diaginertia="0.001 0.001 0.001"/>
                      <body name="r_forearm_cam_optical_frame" quat="0.5 -0.5 0.5 -0.5"/>
                    </body>
                  </body>
                </body>
              </body>
            </body>
          </body>
        </body>

        <body name="l_shoulder_pan_link" pos="0 0.188 0">
          <inertial pos="-0.001201 0.024513 -0.098231" quat="0.927482 -0.0876561 0.0740595 -0.355821" mass="25.7993" diaginertia="0.934201 0.837701 0.242033"/>
          <joint name="l_shoulder_pan_joint" pos="0 0 0" axis="0 0 1" range="-0.000714602 2.2854" actuatorfrcrange="-30 30" damping="10"/>
          <geom type="mesh" contype="0" conaffinity="0" group="1" density="0" rgba="0 0 0.8 1" mesh="shoulder_pan"/>
          <body name="l_shoulder_lift_link" pos="0.1 0 0">
            <inertial pos="0.02195 -0.02664 -0.03127" quat="0.791779 0.478014 0.238985 0.295762" mass="2.74988" diaginertia="0.0261874 0.0207302 0.0151681"/>
            <joint name="l_shoulder_lift_joint" pos="0 0 0" axis="0 1 0" range="-0.5236 1.3963" actuatorfrcrange="-200 200" damping="10"/>
            <geom type="mesh" contype="0" conaffinity="0" group="1" density="0" rgba="0.7 0.7 0.7 1" mesh="shoulder_lift"/>
            <body name="l_upper_arm_roll_link">
              <inertial pos="0 0 0" mass="0.1" diaginertia="0.01 0.01 0.01"/>
              <joint name="l_upper_arm_roll_joint" pos="0 0 0" axis="1 0 0" range="-0.0008 3.9" actuatorfrcrange="-100 100" damping="0.1"/>
              <geom type="mesh" contype="0" conaffinity="0" group="1" density="0" mesh="upper_arm_roll"/>
              <body name="l_upper_arm_link">
                <inertial pos="0.21405 0.01658 -0.00057" quat="-0.0909011 0.708675 -0.0516381 0.697746" mass="6.01769" diaginertia="0.0760697 0.0748821 0.0151071"/>
                <geom type="mesh" contype="0" conaffinity="0" group="1" density="0" rgba="0 0.8 0 1" mesh="upper_arm"/>
                <body name="l_elbow_flex_link" pos="0.4 0 0">
                  <inertial pos="0.01014 0.00032 -0.01211" quat="0.308784 0.646797 0.639077 0.279083" mass="1.90327" diaginertia="0.00441852 0.00396477 0.00308977"/>
                  <joint name="l_elbow_flex_joint" pos="0 0 0" axis="0 1 0" range="-2.3213 0" actuatorfrcrange="-100 100" damping="1"/>
                  <geom type="mesh" contype="0" conaffinity="0" group="1" density="0" rgba="0.7 0.7 0.7 1" mesh="elbow_flex"/>
                  <body name="l_forearm_roll_link">
                    <inertial pos="0 0 0" mass="0.1" diaginertia="0.01 0.01 0.01"/>
                    <joint name="l_forearm_roll_joint" pos="0 0 0" axis="1 0 0" range="-300 300" actuatorfrcrange="-30 30" damping="0.1"/>
                    <geom type="mesh" contype="0" conaffinity="0" group="1" density="0" mesh="forearm_roll"/>
                    <body name="l_forearm_link">
                      <inertial pos="0.18791 -0.00017 -0.00912" quat="-0.000586594 0.726286 -0.00396869 0.687381" mass="2.57968" diaginertia="0.0166326 0.0150775 0.00360892"/>
                      <geom type="mesh" contype="2" conaffinity="2" group="1" density="0" rgba="0.7 0.7 0.7 1" mesh="forearm"/>
                      <body name="l_wrist_flex_link" pos="0.321 0 0">
                        <inertial pos="-0.00157 0 -0.00075" quat="0.695976 0.696411 -0.12356 0.123942" mass="0.61402" diaginertia="0.000652771 0.000643391 0.000198244"/>
                        <joint name="l_wrist_flex_joint" pos="0 0 0" axis="0 1 0" range="-2.18 0" actuatorfrcrange="-30 30" damping="0.1"/>
                        <geom type="mesh" contype="0" conaffinity="0" group="1" density="0" rgba="0.7 0.7 0.7 1" mesh="wrist_flex"/>
                        <body name="l_wrist_roll_link">
                          <inertial pos="0 0 0" mass="0.1" diaginertia="0.01 0.01 0.01"/>
                          <joint name="l_wrist_roll_joint" pos="0 0 0" axis="1 0 0" range="-300 300" actuatorfrcrange="-10 10" damping="0.1"/>
                          <geom type="mesh" contype="0" conaffinity="0" group="1" density="0" mesh="wrist_roll"/>
                          <body name="l_wrist_ft_link" pos="0.03 0 0">
                            <inertial pos="0 0 0" mass="0.0001" diaginertia="1e-6 1e-6 1e-6"/>
                            <site name="l_wrist_ft_site" type="cylinder" pos="0 0 0" zaxis="1 0 0" size="0.02 0.001" rgba="0 0 1 1"/>
                            <body name="l_gripper_palm_link" pos="-0.03 0 0">
                              <inertial pos="0.06623 0.00053 -0.00119" quat="-0.0181842 0.706274 0.0160771 0.707523" mass="0.58007" diaginertia="0.000865637 0.000678178 0.000351471"/>
                              <geom type="mesh" contype="0" conaffinity="0" group="1" density="0" rgba="0.8 0 0 1" mesh="gripper_palm"/>
                              <body name="l_gripper_led_frame" pos="0.0513 0 0.0244"/>
                              <body name="l_gripper_tool_frame" pos="0.18 0 0"/>
                                <body name="l_gripper_l_finger_link" pos="0.07691 0.01 0">
                                <inertial pos="0.03598 0.0173 -0.00164" quat="0.57444 0.429111 0.518782 0.465562" mass="0.17126" diaginertia="0.00019774 0.000181336 7.66239e-05"/>
                                <joint name="l_gripper_l_finger_joint" pos="0 0 0" axis="0 0 1" range="0 0.548" actuatorfrcrange="-1000 1000" damping="0.02"/>
                                <geom type="mesh" contype="0" conaffinity="0" group="1" density="0" rgba="0.7 0.7 0.7 1" mesh="l_finger"/>
                                <geom type="mesh" rgba="0.7 0.7 0.7 1" mesh="l_finger"/>
                                <body name="l_gripper_l_finger_tip_link" pos="0.09137 0.00495 0">
                                  <inertial pos="0.00423 0.00284 0" quat="0.249588 0.661594 -0.249588 0.661594" mass="0.04419" diaginertia="1.54177e-05 1.50049e-05 3.23624e-06"/>
                                  <joint name="l_gripper_l_finger_tip_joint" pos="0 0 0" axis="0 0 -1" range="0 0.548" actuatorfrcrange="-1000 1000" damping="0.001"/>
                                  <geom type="mesh" contype="0" conaffinity="0" group="1" density="0" rgba="0 0.8 0 1" mesh="l_finger_tip"/>
                                  <geom type="mesh" rgba="0 0.8 0 1" mesh="l_finger_tip"/>
                                </body>
                              </body>
                              <body name="l_gripper_r_finger_link" pos="0.07691 -0.01 0">
                                <inertial pos="0.03576 -0.01736 -0.00095" quat="0.474684 0.510909 0.446353 0.560727" mass="0.17389" diaginertia="0.000198903 0.00018134 7.66847e-05"/>
                                <joint name="l_gripper_r_finger_joint" pos="0 0 0" axis="0 0 -1" range="0 0.548" actuatorfrcrange="-1000 1000" damping="0.02"/>
                                <geom quat="0 1 0 0" type="mesh" contype="0" conaffinity="0" group="1" density="0" rgba="0.7 0.7 0.7 1" mesh="l_finger"/>
                                <geom quat="0 1 0 0" type="mesh" rgba="0.7 0.7 0.7 1" mesh="l_finger"/>
                                <body name="l_gripper_r_finger_tip_link" pos="0.09137 -0.00495 0">
                                  <inertial pos="0.00423 -0.00284 0" quat="-0.249588 0.661594 0.249588 0.661594" mass="0.04419" diaginertia="1.54177e-05 1.50049e-05 3.23624e-06"/>
                                  <joint name="l_gripper_r_finger_tip_joint" pos="0 0 0" axis="0 0 1" range="0 0.548" actuatorfrcrange="-1000 1000" damping="0.001"/>
                                  <geom quat="0 1 0 0" type="mesh" contype="0" conaffinity="0" group="1" density="0" rgba="0 0.8 0 1" mesh="l_finger_tip"/>
                                  <geom quat="0 1 0 0" type="mesh" rgba="0 0.8 0 1" mesh="l_finger_tip"/>
                                  <body name="l_gripper_l_finger_tip_frame">
                                    <inertial pos="0 0 0" mass="0.001" diaginertia="1e-06 1e-06 1e-06"/>
                                    <joint name="l_gripper_joint" pos="0 0 0" axis="0 1 0" type="slide" range="0 0.09" actuatorfrcrange="-1000 1000" damping="10"/>
                                  </body>
                                </body>
                              </body>
                            </body>
                          </body>
                        </body>
                      </body>
                    </body>
                    <body name="l_forearm_cam_frame" pos="0.135 0 0.044" quat="0.679288 -0.679288 -0.196387 -0.196387">
                      <inertial pos="0 0 0" mass="0.01" diaginertia="0.001 0.001 0.001"/>
                      <body name="l_forearm_cam_optical_frame" quat="0.5 -0.5 0.5 -0.5"/>
                    </body>
                  </body>
                </body>
              </body>
            </body>
          </body>
        </body>
        
        <body name="torso_lift_motor_screw_link" pos="-0.15 0 0.7">
          <inertial pos="0 0 0" mass="1" diaginertia="0.001 0.001 0.001"/>
        </body>
      </body>
    </body>
  </worldbody>

  <equality>
    <joint joint1 ="r_gripper_l_finger_joint" joint2 ="r_gripper_r_finger_joint" polycoef="0 1 0 0 0" solref="0.001 1" solimp="0.95 0.99 0.001"/>
    <joint joint1 ="l_gripper_l_finger_joint" joint2 ="l_gripper_r_finger_joint" polycoef="0 1 0 0 0" solref="0.001 1" solimp="0.95 0.99 0.001"/>
    <joint joint1 ="r_gripper_l_finger_tip_joint" joint2 ="r_gripper_r_finger_tip_joint" polycoef="0 1 0 0 0" solref="0.001 1" solimp="0.95 0.99 0.001"/>
    <joint joint1 ="l_gripper_l_finger_tip_joint" joint2 ="l_gripper_r_finger_tip_joint" polycoef="0 1 0 0 0" solref="0.001 1" solimp="0.95 0.99 0.001"/>
    <joint joint1 ="r_gripper_l_finger_joint" joint2 ="r_gripper_l_finger_tip_joint" polycoef="0 1 0 0 0" solref="0.001 1" solimp="0.95 0.99 0.001"/>
    <joint joint1 ="l_gripper_l_finger_joint" joint2 ="l_gripper_l_finger_tip_joint" polycoef="0 1 0 0 0" solref="0.001 1" solimp="0.95 0.99 0.001"/>
  </equality>

  <actuator>
    <position name="r_gripper_pos" joint="r_gripper_l_finger_joint" kp="40" kv="1.2" ctrllimited="true" ctrlrange="0.01 0.548"/>
    <position name="l_gripper_pos" joint="l_gripper_l_finger_joint" kp="40" kv="1.2" ctrllimited="true" ctrlrange="0.01 0.548"/>
    <position name="head_pan_pos" joint="head_pan_joint" kp="50" kv="20" ctrllimited="true" ctrlrange="-2.645 2.645"/>
    <position name="head_tilt_pos" joint="head_tilt_joint" kp="50" kv="20" ctrllimited="true" ctrlrange="-0.471238 1.39626"/>
    <position name="laser_tilt_pos" joint="laser_tilt_mount_joint" kp="100" kv="10" ctrllimited="true" ctrlrange="-0.65 0.65"/>

    <position name="fl_caster_steer" joint="fl_caster_rotation_joint" kp="100" kv="5" ctrllimited="true" ctrlrange="-3000 3000"/>
    <position name="fr_caster_steer" joint="fr_caster_rotation_joint" kp="100" kv="5" ctrllimited="true" ctrlrange="-3000 3000"/>
    <position name="bl_caster_steer" joint="bl_caster_rotation_joint" kp="100" kv="5" ctrllimited="true" ctrlrange="-3000 3000"/>
    <position name="br_caster_steer" joint="br_caster_rotation_joint" kp="100" kv="5" ctrllimited="true" ctrlrange="-3000 3000"/>

    <velocity name="fl_caster_l_wheel_vel" joint="fl_caster_l_wheel_joint" kv="10" ctrllimited="true" ctrlrange="-20 20"/>
    <velocity name="fl_caster_r_wheel_vel" joint="fl_caster_r_wheel_joint" kv="10" ctrllimited="true" ctrlrange="-20 20"/>
    <velocity name="fr_caster_l_wheel_vel" joint="fr_caster_l_wheel_joint" kv="10" ctrllimited="true" ctrlrange="-20 20"/>
    <velocity name="fr_caster_r_wheel_vel" joint="fr_caster_r_wheel_joint" kv="10" ctrllimited="true" ctrlrange="-20 20"/>
    <velocity name="bl_caster_l_wheel_vel" joint="bl_caster_l_wheel_joint" kv="10" ctrllimited="true" ctrlrange="-20 20"/>
    <velocity name="bl_caster_r_wheel_vel" joint="bl_caster_r_wheel_joint" kv="10" ctrllimited="true" ctrlrange="-20 20"/>
    <velocity name="br_caster_l_wheel_vel" joint="br_caster_l_wheel_joint" kv="10" ctrllimited="true" ctrlrange="-20 20"/>
    <velocity name="br_caster_r_wheel_vel" joint="br_caster_r_wheel_joint" kv="10" ctrllimited="true" ctrlrange="-20 20"/>

    <motor name="torso_lift_tau" joint="torso_lift_joint" gear="1" ctrllimited="true" ctrlrange="-10000 10000"/>
    
    <motor name="r_shoulder_pan_tau"   joint="r_shoulder_pan_joint" gear="1" ctrllimited="true" ctrlrange="-30 30"/>
    <motor name="r_shoulder_lift_tau"  joint="r_shoulder_lift_joint" gear="1" ctrllimited="true" ctrlrange="-200 200"/>
    <motor name="r_upper_arm_roll_tau" joint="r_upper_arm_roll_joint" gear="1" ctrllimited="true" ctrlrange="-100 100"/>
    <motor name="r_elbow_flex_tau"     joint="r_elbow_flex_joint" gear="1" ctrllimited="true" ctrlrange="-100 100"/>
    <motor name="r_forearm_roll_tau"   joint="r_forearm_roll_joint" gear="1" ctrllimited="true" ctrlrange="-30 30"/>
    <motor name="r_wrist_flex_tau"     joint="r_wrist_flex_joint" gear="1" ctrllimited="true" ctrlrange="-30 30"/>
    <motor name="r_wrist_roll_tau"     joint="r_wrist_roll_joint" gear="1" ctrllimited="true" ctrlrange="-10 10"/>

    <motor name="l_shoulder_pan_tau"   joint="l_shoulder_pan_joint" gear="1" ctrllimited="true" ctrlrange="-200 200"/>
    <motor name="l_shoulder_lift_tau"  joint="l_shoulder_lift_joint" gear="1" ctrllimited="true" ctrlrange="-200 200"/>
    <motor name="l_upper_arm_roll_tau" joint="l_upper_arm_roll_joint" gear="1" ctrllimited="true" ctrlrange="-100 100"/>
    <motor name="l_elbow_flex_tau"     joint="l_elbow_flex_joint" gear="1" ctrllimited="true" ctrlrange="-100 100"/>
    <motor name="l_forearm_roll_tau"   joint="l_forearm_roll_joint" gear="1" ctrllimited="true" ctrlrange="-30 30"/>
    <motor name="l_wrist_flex_tau"     joint="l_wrist_flex_joint" gear="1" ctrllimited="true" ctrlrange="-30 30"/>
    <motor name="l_wrist_roll_tau"     joint="l_wrist_roll_joint" gear="1" ctrllimited="true" ctrlrange="-10 10"/>
  </actuator>

  <sensor>
    <jointpos name="torso_lift_q"  joint="torso_lift_joint"/>
    <jointvel name="torso_lift_dq" joint="torso_lift_joint"/>

    <jointpos name="r_shoulder_pan_q"   joint="r_shoulder_pan_joint"/>
    <jointvel name="r_shoulder_pan_dq"  joint="r_shoulder_pan_joint"/>
    <jointpos name="r_shoulder_lift_q"  joint="r_shoulder_lift_joint"/>
    <jointvel name="r_shoulder_lift_dq" joint="r_shoulder_lift_joint"/>
    <jointpos name="r_upper_arm_roll_q"   joint="r_upper_arm_roll_joint"/>
    <jointvel name="r_upper_arm_roll_dq"  joint="r_upper_arm_roll_joint"/>
    <jointpos name="r_elbow_flex_q"   joint="r_elbow_flex_joint"/>
    <jointvel name="r_elbow_flex_dq"  joint="r_elbow_flex_joint"/>
    <jointpos name="r_forearm_roll_q"   joint="r_forearm_roll_joint"/>
    <jointvel name="r_forearm_roll_dq"  joint="r_forearm_roll_joint"/>
    <jointpos name="r_wrist_flex_q"   joint="r_wrist_flex_joint"/>
    <jointvel name="r_wrist_flex_dq"  joint="r_wrist_flex_joint"/>
    <jointpos name="r_wrist_roll_q"   joint="r_wrist_roll_joint"/>
    <jointvel name="r_wrist_roll_dq"  joint="r_wrist_roll_joint"/>

    <jointpos name="l_shoulder_pan_q"   joint="l_shoulder_pan_joint"/>
    <jointvel name="l_shoulder_pan_dq"  joint="l_shoulder_pan_joint"/>
    <jointpos name="l_shoulder_lift_q"  joint="l_shoulder_lift_joint"/>
    <jointvel name="l_shoulder_lift_dq" joint="l_shoulder_lift_joint"/>
    <jointpos name="l_upper_arm_roll_q"   joint="l_upper_arm_roll_joint"/>
    <jointvel name="l_upper_arm_roll_dq"  joint="l_upper_arm_roll_joint"/>
    <jointpos name="l_elbow_flex_q"   joint="l_elbow_flex_joint"/>
    <jointvel name="l_elbow_flex_dq"  joint="l_elbow_flex_joint"/>
    <jointpos name="l_forearm_roll_q"   joint="l_forearm_roll_joint"/>
    <jointvel name="l_forearm_roll_dq"  joint="l_forearm_roll_joint"/>
    <jointpos name="l_wrist_flex_q"   joint="l_wrist_flex_joint"/>
    <jointvel name="l_wrist_flex_dq"  joint="l_wrist_flex_joint"/>
    <jointpos name="l_wrist_roll_q"   joint="l_wrist_roll_joint"/>
    <jointvel name="l_wrist_roll_dq"  joint="l_wrist_roll_joint"/>

    <jointpos name="fl_caster_rotation_q" joint="fl_caster_rotation_joint"/>
    <jointpos name="fr_caster_rotation_q" joint="fr_caster_rotation_joint"/>
    <jointpos name="bl_caster_rotation_q" joint="bl_caster_rotation_joint"/>
    <jointpos name="br_caster_rotation_q" joint="br_caster_rotation_joint"/>

    <jointpos name="fl_caster_l_wheel_q"  joint="fl_caster_l_wheel_joint"/>
    <jointvel name="fl_caster_l_wheel_dq" joint="fl_caster_l_wheel_joint"/>
    <jointpos name="fl_caster_r_wheel_q"  joint="fl_caster_r_wheel_joint"/>
    <jointvel name="fl_caster_r_wheel_dq" joint="fl_caster_r_wheel_joint"/>

    <jointpos name="fr_caster_l_wheel_q"  joint="fr_caster_l_wheel_joint"/>
    <jointvel name="fr_caster_l_wheel_dq" joint="fr_caster_l_wheel_joint"/>
    <jointpos name="fr_caster_r_wheel_q"  joint="fr_caster_r_wheel_joint"/>
    <jointvel name="fr_caster_r_wheel_dq" joint="fr_caster_r_wheel_joint"/>

    <jointpos name="bl_caster_l_wheel_q"  joint="bl_caster_l_wheel_joint"/>
    <jointvel name="bl_caster_l_wheel_dq" joint="bl_caster_l_wheel_joint"/>
    <jointpos name="bl_caster_r_wheel_q"  joint="bl_caster_r_wheel_joint"/>
    <jointvel name="bl_caster_r_wheel_dq" joint="bl_caster_r_wheel_joint"/>

    <jointpos name="br_caster_l_wheel_q"  joint="br_caster_l_wheel_joint"/>
    <jointvel name="br_caster_l_wheel_dq" joint="br_caster_l_wheel_joint"/>
    <jointpos name="br_caster_r_wheel_q"  joint="br_caster_r_wheel_joint"/>
    <jointvel name="br_caster_r_wheel_dq" joint="br_caster_r_wheel_joint"/>
      
    <framepos name='pr2/base_pos' objtype='site' objname='pr2_base_sensor' />
    <framequat name='pr2/base_quat' objtype='site' objname='pr2_base_sensor' />
      
    <force name="pr2/right_force" site="r_wrist_ft_site" />
    <torque name="pr2/right_torque" site="r_wrist_ft_site" />
    <force name="pr2/left_force" site="l_wrist_ft_site" />
    <torque name="pr2/left_torque" site="l_wrist_ft_site" />
  </sensor>
</mujoco>